In Next.js 15, a particularly uncommon bug can arise when using server components with a poorly structured data fetching mechanism.  Imagine a scenario where you're fetching data within a server component using `async/await` and handling potential errors with a `try...catch` block.  However, the `catch` block doesn't explicitly handle all potential error types, leading to a cryptic error that only manifests in production.

```javascript
// pages/api/data.js

export default async function handler(req, res) {
  try {
    const data = await fetchData(); // Simulates fetching data
    res.status(200).json(data);
  } catch (error) {
    console.error('Error fetching data:', error);
    res.status(500).json({ error: 'Failed to fetch data' });
  }
}

async function fetchData() {
  //Simulate network error
  if(Math.random() < 0.5) throw new Error('Network error');
  return { message: 'Data fetched successfully' };
}

```

```javascript
// app/page.js
import {getServerSession} from 'next-auth/next'  

export default async function Home() {
  const session = await getServerSession();
  const res = await fetch('/api/data');
  const data = await res.json();

  if (res.status !== 200) {
    throw new Error(`Failed to fetch data: ${data.error}`);
  }
  return (
    <div>{data.message}</div>
  );
}
```